Workbook

Sheet Cover
E5: Alphabet Inc.
E6: Valuation Model
E9: NASDAQ: GOOGL / GOOG
E11: Prepared by: Nathan Adabra
E12: Valuation Date: | F12: 46231
E13: Currency | F13: USD
E17: Assumptions • Three-Statement Model • Supporting Schedules • DCF • Sensitivity Analysis

Sheet Assumptions
B2: Assumptions
B4: Driver | C4: Historical | E4: Forecast
C5: FY2024A | D5: FY2025A | E5: FY2026E | F5: FY2027E | G5: FY2028E | H5: FY2029E | I5: FY2030E
B7: Growth
B8: Revenue Growth (%) | C8: =('Income Statement'!D11-'Income Statement'!C11)/'Income Statement'!C11 -> 0.13866243 | D8: =('Income Statement'!E11-'Income Statement'!D11)/'Income Statement'!D11 -> 0.15090081 | E8: 0.14 | F8: 0.13 | G8: 0.12 | H8: 0.11 | I8: 0.1
B10: Margins
B11: Gross Margin (%) | C11: ='Income Statement'!D19/'Income Statement'!D11 -> 0.58200435 | D11: ='Income Statement'!E19/'Income Statement'!E11 -> 0.59652315 | E11: 0.595 | F11: 0.598 | G11: 0.6 | H11: 0.602 | I11: 0.604
B12: R&D (% Revenue) | C12: ='Income Statement'!D22/'Income Statement'!D11 -> 0.14092418 | D12: ='Income Statement'!E22/'Income Statement'!E11 -> 0.15164236 | E12: 0.152 | F12: 0.15 | G12: 0.148 | H12: 0.146 | I12: 0.144
B13: Sales and Marketing (% Revenue) | C13: ='Income Statement'!D23/'Income Statement'!D11 -> 0.079447343 | D13: ='Income Statement'!E23/'Income Statement'!E11 -> 0.071227497 | E13: 0.071 | F13: 0.0705 | G13: 0.07 | H13: 0.0695 | I13: 0.069
B14: G&A (% Revenue) | C14: ='Income Statement'!D24/'Income Statement'!D11 -> 0.040535058 | D14: ='Income Statement'!E24/'Income Statement'!E11 -> 0.053326912 | E14: 0.053 | F14: 0.052 | G14: 0.051 | H14: 0.05 | I14: 0.05
B15: Implied Operating Margin (%) | C15: ='Income Statement'!D28/'Income Statement'!D11 -> 0.32109777 | D15: ='Income Statement'!E28/'Income Statement'!E11 -> 0.32032639 | E15: ='Income Statement'!F28/'Income Statement'!F11 -> 0.319 | F15: ='Income Statement'!G28/'Income Statement'!G11 -> 0.3255 | G15: ='Income Statement'!H28/'Income Statement'!H11 -> 0.331 | H15: ='Income Statement'!I28/'Income Statement'!I11 -> 0.3365 | I15: ='Income Statement'!J28/'Income Statement'!J11 -> 0.341
B16: Tax Rate (%) | C16: ='Income Statement'!D34/'Income Statement'!D32 -> 0.16401118 | D16: ='Income Statement'!E34/'Income Statement'!E32 -> 0.13722564 | E16: 0.18 | F16: 0.18 | G16: 0.18 | H16: 0.18 | I16: 0.18
B18: Investment
B19: CapEx (% Revenue) | C19: =ABS('Cash Flow Statement'!D30)/'Income Statement'!D11 -> 0.15009228 | D19: =ABS('Cash Flow Statement'!E30)/'Income Statement'!E11 -> 0.22700801 | E19: 0.3 | F19: 0.27 | G19: 0.24 | H19: 0.22 | I19: 0.2
B20: Depreciation (% Revenue) | C20: ='Cash Flow Statement'!D11/'Income Statement'!D11 -> 0.043743465 | D20: ='Cash Flow Statement'!E11/'Income Statement'!E11 -> 0.052468002 | E20: 0.06 | F20: 0.065 | G20: 0.07 | H20: 0.072 | I20: 0.074
B21: Investment Purchases (% Revenue) | C21: =ABS('Cash Flow Statement'!D32)/'Income Statement'!D11 -> 0.24764155 | D21: =ABS('Cash Flow Statement'!E32)/'Income Statement'!E11 -> 0.25760607 | E21: 0.22 | F21: 0.2 | G21: 0.18 | H21: 0.16 | I21: 0.15
B23: Working Capital
B24: Accounts Receivable (% Revenue) | C24: ='Balance Sheet'!D14/'Income Statement'!D11 -> 0.14953517 | D24: ='Balance Sheet'!E14/'Income Statement'!E11 -> 0.15610819 | E24: 0.156 | F24: 0.156 | G24: 0.156 | H24: 0.156 | I24: 0.156
B25: Inventory (% Revenue) | C25: ='Balance Sheet'!D15/'Income Statement'!D11 -> 0 | D25: ='Balance Sheet'!E15/'Income Statement'!E11 -> 0 | E25: 0 | F25: 0 | G25: 0 | H25: 0 | I25: 0
B26: Accounts Payable (% Revenue) | C26: ='Balance Sheet'!D35/'Income Statement'!D11 -> 0.022818826 | D26: ='Balance Sheet'!E35/'Income Statement'!E11 -> 0.030285277 | E26: 0.03 | F26: 0.03 | G26: 0.03 | H26: 0.03 | I26: 0.03
B28: Capital Allocation
B29: Dividend Growth (%) | C29: =(ABS('Cash Flow Statement'!D45)-ABS('Cash Flow Statement'!C45))/ABS('Cash Flow Statement'!C45) -> #DIV/0! | D29: =(ABS('Cash Flow Statement'!E45)-ABS('Cash Flow Statement'!D45))/ABS('Cash Flow Statement'!D45) -> 0.36479696 | E29: 0.1 | F29: 0.1 | G29: 0.09 | H29: 0.09 | I29: 0.08

Sheet Income Statement
B2: Income Statement
B4: ($ in millions, except per share data) | C4: Historical | F4: Forecast
C5: FY2023A | D5: FY2024A | E5: FY2025A | F5: FY2026E | G5: FY2027E | H5: FY2028E | I5: FY2029E | J5: FY2030E
B7: Revenue:
B8: Total Revenues | C8: 307394 | D8: 350018 | E8: 402836 | F8: =E8*(1+Assumptions!E8) -> 459233.04 | G8: =F8*(1+Assumptions!F8) -> 518933.34 | H8: =G8*(1+Assumptions!G8) -> 581205.34 | I8: =H8*(1+Assumptions!H8) -> 645137.92 | J8: =I8*(1+Assumptions!I8) -> 709651.71
C9: 0 | D9: 0 | E9: 0 | F9: =E9*(1+Assumptions!E8) -> 0 | G9: =F9*(1+Assumptions!F8) -> 0 | H9: =G9*(1+Assumptions!G8) -> 0 | I9: =H9*(1+Assumptions!H8) -> 0 | J9: =I9*(1+Assumptions!I8) -> 0
B11: Total Revenue | C11: =SUM(C8:C9) -> 307394 | D11: =SUM(D8:D9) -> 350018 | E11: =SUM(E8:E9) -> 402836 | F11: =SUM(F8:F9) -> 459233.04 | G11: =SUM(G8:G9) -> 518933.34 | H11: =SUM(H8:H9) -> 581205.34 | I11: =SUM(I8:I9) -> 645137.92 | J11: =SUM(J8:J9) -> 709651.71
B13: Cost of Revenue:
B14: Cost of Revenues | C14: 133332 | D14: 146306 | E14: 162535
C15: 0 | D15: 0 | E15: 0
B17: Total Cost of Revenue | C17: =SUM(C14:C15) -> 133332 | D17: =SUM(D14:D15) -> 146306 | E17: =SUM(E14:E15) -> 162535 | F17: =F11-F19 -> 185989.38 | G17: =G11-G19 -> 208611.2 | H17: =H11-H19 -> 232482.13 | I17: =I11-I19 -> 256764.89 | J17: =J11-J19 -> 281022.08
B19: Gross Profit | C19: =C11-C17 -> 174062 | D19: =D11-D17 -> 203712 | E19: =E11-E17 -> 240301 | F19: =F11*Assumptions!E11 -> 273243.66 | G19: =G11*Assumptions!F11 -> 310322.13 | H19: =H11*Assumptions!G11 -> 348723.2 | I19: =I11*Assumptions!H11 -> 388373.03 | J19: =J11*Assumptions!I11 -> 428629.64
B21: Operating Expenses:
B22: Research and Development | C22: 45427 | D22: 49326 | E22: 61087 | F22: =F11*Assumptions!E12 -> 69803.422 | G22: =G11*Assumptions!F12 -> 77840 | H22: =H11*Assumptions!G12 -> 86018.39 | I22: =I11*Assumptions!H12 -> 94190.137 | J22: =J11*Assumptions!I12 -> 102189.85
B23: Sales and Marketing | C23: 27917 | D23: 27808 | E23: 28693 | F23: =F11*Assumptions!E13 -> 32605.546 | G23: =G11*Assumptions!F13 -> 36584.8 | H23: =H11*Assumptions!G13 -> 40684.373 | I23: =I11*Assumptions!H13 -> 44837.086 | J23: =J11*Assumptions!I13 -> 48965.968
B24: General and Administrative | C24: 16425 | D24: 14188 | E24: 21482 | F24: =F11*Assumptions!E14 -> 24339.351 | G24: =G11*Assumptions!F14 -> 26984.533 | H24: =H11*Assumptions!G14 -> 29641.472 | I24: =I11*Assumptions!H14 -> 32256.896 | J24: =J11*Assumptions!I14 -> 35482.586
B26: Total Operating Expenses | C26: =SUM(C22:C24) -> 89769 | D26: =SUM(D22:D24) -> 91322 | E26: =SUM(E22:E24) -> 111262 | F26: =SUM(F22:F24) -> 126748.32 | G26: =SUM(G22:G24) -> 141409.33 | H26: =SUM(H22:H24) -> 156344.24 | I26: =SUM(I22:I24) -> 171284.12 | J26: =SUM(J22:J24) -> 186638.4
B28: Operating Income | C28: =C19-C26 -> 84293 | D28: =D19-D26 -> 112390 | E28: =E19-E26 -> 129039 | F28: =F19-F26 -> 146495.34 | G28: =G19-G26 -> 168912.8 | H28: =H19-H26 -> 192378.97 | I28: =I19-I26 -> 217088.91 | J28: =J19-J26 -> 241991.23
B30: Other Income (expense), Net | C30: 1424 | D30: 7425 | E30: 29787 | F30: 8000 | G30: 8000 | H30: 8000 | I30: 8000 | J30: 8000
B32: Income before taxes | C32: =SUM(C28:C30) -> 85717 | D32: =SUM(D28:D30) -> 119815 | E32: =SUM(E28:E30) -> 158826 | F32: =SUM(F28:F30) -> 154495.34 | G32: =SUM(G28:G30) -> 176912.8 | H32: =SUM(H28:H30) -> 200378.97 | I32: =SUM(I28:I30) -> 225088.91 | J32: =SUM(J28:J30) -> 249991.23
B34: Income Tax Expense | C34: 16950 | D34: 19651 | E34: 21795 | F34: =F32*Assumptions!E16 -> 27809.161 | G34: =G32*Assumptions!F16 -> 31844.304 | H34: =H32*Assumptions!G16 -> 36068.214 | I34: =I32*Assumptions!H16 -> 40516.004 | J34: =J32*Assumptions!I16 -> 44998.422
B36: Net Income | C36: =C32-C34 -> 68767 | D36: =D32-D34 -> 100164 | E36: =E32-E34 -> 137031 | F36: =F32-F34 -> 126686.18 | G36: =G32-G34 -> 145068.5 | H36: =H32-H34 -> 164310.75 | I36: =I32-I34 -> 184572.91 | J36: =J32-J34 -> 204992.81
B38: Earnings Per Share:
B39: Basic | C39: =C36/C43 -> 5.4447348 | D39: =D36/D43 -> 8.1308548 | E39: =E36/E43 -> 11.309921 | F39: =F36/F43 -> 10.456106 | G39: =G36/G43 -> 11.973299 | H39: =H36/H43 -> 13.561468 | I39: =I36/I43 -> 15.233815 | J39: =J36/J43 -> 16.919182
B40: Diluted | C40: =C36/C44 -> 5.4053608 | D40: =D36/D44 -> 8.0472403 | E40: =E36/E44 -> 11.204497 | F40: =F36/F44 -> 10.358641 | G40: =G36/G44 -> 11.861692 | H40: =H36/H44 -> 13.435057 | I40: =I36/I44 -> 15.091816 | J40: =J36/J44 -> 16.761473
B42: Weighted Average Shares Outstanding:
B43: Basic | C43: 12630 | D43: 12319 | E43: 12116 | F43: =E43 -> 12116 | G43: =F43 -> 12116 | H43: =G43 -> 12116 | I43: =H43 -> 12116 | J43: =I43 -> 12116
B44: Diluted | C44: 12722 | D44: 12447 | E44: 12230 | F44: =E44 -> 12230 | G44: =F44 -> 12230 | H44: =G44 -> 12230 | I44: =H44 -> 12230 | J44: =I44 -> 12230

Sheet Balance Sheet
B2: Balance Sheet
B4: ($ in millions) | C4: Historical | F4: Forecast
C5: FY2023A | D5: FY2024A | E5: FY2025A | F5: FY2026E | G5: FY2027E | H5: FY2028E | I5: FY2029E | J5: FY2030E
B7: Assets
B9: Current Assets:
B10: Cash and Cash Equivalents | C10: 24048 | D10: 23466 | E10: 30708 | F10: ='Cash Flow Statement'!F56 -> -72084.283 | G10: ='Cash Flow Statement'!G56 -> -156865.31 | H10: ='Cash Flow Statement'!H56 -> -217076.33 | I10: ='Cash Flow Statement'!I56 -> -253707.86 | J10: ='Cash Flow Statement'!J56 -> -268309.83
B11: Short-term Investments | C11: 86868 | D11: 72191 | E11: 96135 | F11: =E11-'Cash Flow Statement'!F32 -> 197166.27 | G11: =F11-'Cash Flow Statement'!G32 -> 300952.94 | H11: =G11-'Cash Flow Statement'!H32 -> 405569.9 | I11: =H11-'Cash Flow Statement'!I32 -> 508791.96 | J11: =I11-'Cash Flow Statement'!J32 -> 615239.72
B13: Total Cash and Short-Term Investments | C13: =SUM(C10:C11) -> 110916 | D13: =SUM(D10:D11) -> 95657 | E13: =SUM(E10:E11) -> 126843 | F13: =SUM(F10:F11) -> 125081.99 | G13: =SUM(G10:G11) -> 144087.62 | H13: =SUM(H10:H11) -> 188493.57 | I13: =SUM(I10:I11) -> 255084.1 | J13: =SUM(J10:J11) -> 346929.89
B14: Accounts Receivable, Net | C14: 47964 | D14: 52340 | E14: 62886 | F14: ='Income Statement'!F11*Assumptions!E24 -> 71640.354 | G14: ='Income Statement'!G11*Assumptions!F24 -> 80953.6 | H14: ='Income Statement'!H11*Assumptions!G24 -> 90668.032 | I14: ='Income Statement'!I11*Assumptions!H24 -> 100641.52 | J14: ='Income Statement'!J11*Assumptions!I24 -> 110705.67
B15: Inventories | C15: 0 | D15: 0 | E15: 0 | F15: ='Income Statement'!F11*Assumptions!E25 -> 0 | G15: ='Income Statement'!G11*Assumptions!F25 -> 0 | H15: ='Income Statement'!H11*Assumptions!G25 -> 0 | I15: ='Income Statement'!I11*Assumptions!H25 -> 0 | J15: ='Income Statement'!J11*Assumptions!I25 -> 0
B16: Other Current Assets | C16: 12650 | D16: 15714 | E16: 16309 | F16: =E16 -> 16309 | G16: =F16 -> 16309 | H16: =G16 -> 16309 | I16: =H16 -> 16309 | J16: =I16 -> 16309
B18: Total Current Assets | C18: =SUM(C13:C16) -> 171530 | D18: =SUM(D13:D16) -> 163711 | E18: =SUM(E13:E16) -> 206038 | F18: =SUM(F13:F16) -> 213031.34 | G18: =SUM(G13:G16) -> 241350.22 | H18: =SUM(H13:H16) -> 295470.6 | I18: =SUM(I13:I16) -> 372034.62 | J18: =SUM(J13:J16) -> 473944.56
B20: Non-Current Assets:
B21: Property and Equipment, Net | C21: 134345 | D21: 171036 | E21: 246597 | F21: =E21-'Cash Flow Statement'!F30-'Cash Flow Statement'!F11 -> 356812.93 | G21: =F21-'Cash Flow Statement'!G30-'Cash Flow Statement'!G11 -> 463194.26 | H21: =G21-'Cash Flow Statement'!H30-'Cash Flow Statement'!H11 -> 561999.17 | I21: =H21-'Cash Flow Statement'!I30-'Cash Flow Statement'!I11 -> 657479.58 | J21: =I21-'Cash Flow Statement'!J30-'Cash Flow Statement'!J11 -> 746895.7
B22: Operating Lease ROU Assets | C22: 14091 | D22: 13588 | E22: 15221 | F22: =E22 -> 15221 | G22: =F22 -> 15221 | H22: =G22 -> 15221 | I22: =H22 -> 15221 | J22: =I22 -> 15221
B23: Equity and Other Investments | C23: 31008 | D23: 37982 | E23: 68687 | F23: =E23 -> 68687 | G23: =F23 -> 68687 | H23: =G23 -> 68687 | I23: =H23 -> 68687 | J23: =I23 -> 68687
B24: Goodwill | C24: 29198 | D24: 31885 | E24: 33380 | F24: =E24 -> 33380 | G24: =F24 -> 33380 | H24: =G24 -> 33380 | I24: =H24 -> 33380 | J24: =I24 -> 33380
B25: Intangible Assets, Net | C25: 0 | D25: 0 | E25: 0 | F25: =E25 -> 0 | G25: =F25 -> 0 | H25: =G25 -> 0 | I25: =H25 -> 0 | J25: =I25 -> 0
B26: Other Long-Term Assets | C26: 22220 | D26: 32054 | E26: 25358 | F26: =E26 -> 25358 | G26: =F26 -> 25358 | H26: =G26 -> 25358 | I26: =H26 -> 25358 | J26: =I26 -> 25358
B28: Total Non-Current Assets | C28: =SUM(C21:C26) -> 230862 | D28: =SUM(D21:D26) -> 286545 | E28: =SUM(E21:E26) -> 389243 | F28: =SUM(F21:F26) -> 499458.93 | G28: =SUM(G21:G26) -> 605840.26 | H28: =SUM(H21:H26) -> 704645.17 | I28: =SUM(I21:I26) -> 800125.58 | J28: =SUM(J21:J26) -> 889541.7
B30: Total Assets | C30: =SUM(C18+C28) -> 402392 | D30: =SUM(D18+D28) -> 450256 | E30: =SUM(E18+E28) -> 595281 | F30: =SUM(F18+F28) -> 712490.27 | G30: =SUM(G18+G28) -> 847190.49 | H30: =SUM(H18+H28) -> 1000115.8 | I30: =SUM(I18+I28) -> 1172160.2 | J30: =SUM(J18+J28) -> 1363486.3
B32: Liabilities and Stockholders' Equity
B34: Current Liabilities:
B35: Accounts Payable | C35: 7493 | D35: 7987 | E35: 12200 | F35: ='Income Statement'!F11*Assumptions!E26 -> 13776.991 | G35: ='Income Statement'!G11*Assumptions!F26 -> 15568 | H35: ='Income Statement'!H11*Assumptions!G26 -> 17436.16 | I35: ='Income Statement'!I11*Assumptions!H26 -> 19354.138 | J35: ='Income Statement'!J11*Assumptions!I26 -> 21289.551
B36: Short-Term Debt | C36: 0 | D36: 0 | E36: 0 | F36: =E36 -> 0 | G36: =F36 -> 0 | H36: =G36 -> 0 | I36: =H36 -> 0 | J36: =I36 -> 0
B37: Current Portion of Long-Term Debt | C37: 0 | D37: 0 | E37: 0 | F37: =E37 -> 0 | G37: =F37 -> 0 | H37: =G37 -> 0 | I37: =H37 -> 0 | J37: =I37 -> 0
B38: Accrued Compensation | C38: 15140 | D38: 15069 | E38: 17546 | F38: =E38 -> 17546 | G38: =F38 -> 17546 | H38: =G38 -> 17546 | I38: =H38 -> 17546 | J38: =I38 -> 17546
B39: Short-Term Income Taxes | C39: 0 | D39: 0 | E39: 0 | F39: =E39 -> 0 | G39: =F39 -> 0 | H39: =G39 -> 0 | I39: =H39 -> 0 | J39: =I39 -> 0
B40: Short-Term Unearned Revenue | C40: 4137 | D40: 5036 | E40: 6578 | F40: =E40 -> 6578 | G40: =F40 -> 6578 | H40: =G40 -> 6578 | I40: =H40 -> 6578 | J40: =I40 -> 6578
B41: Other Current Liabilities | C41: 55044 | D41: 61030 | E41: 66421 | F41: =E41 -> 66421 | G41: =F41 -> 66421 | H41: =G41 -> 66421 | I41: =H41 -> 66421 | J41: =I41 -> 66421
B43: Total Current Liabilities: | C43: =SUM(C35:C41) -> 81814 | D43: =SUM(D35:D41) -> 89122 | E43: =SUM(E35:E41) -> 102745 | F43: =SUM(F35:F41) -> 104321.99 | G43: =SUM(G35:G41) -> 106113 | H43: =SUM(H35:H41) -> 107981.16 | I43: =SUM(I35:I41) -> 109899.14 | J43: =SUM(J35:J41) -> 111834.55
B45: Non-Current Liabilities:
B46: Long-Term Debt | C46: 13253 | D46: 10883 | E46: 46547 | F46: =E46 -> 46547 | G46: =F46 -> 46547 | H46: =G46 -> 46547 | I46: =H46 -> 46547 | J46: =I46 -> 46547
B47: Long-Term Income Taxes | C47: 8474 | D47: 8782 | E47: 9531 | F47: =E47 -> 9531 | G47: =F47 -> 9531 | H47: =G47 -> 9531 | I47: =H47 -> 9531 | J47: =I47 -> 9531
B48: Long-Term Unearned Revenue | C48: 911 | D48: 0 | E48: 0 | F48: =E48 -> 0 | G48: =F48 -> 0 | H48: =G48 -> 0 | I48: =H48 -> 0 | J48: =I48 -> 0
B49: Deferred Income Taxes | C49: 485 | D49: 0 | E49: 0 | F49: =E49 -> 0 | G49: =F49 -> 0 | H49: =G49 -> 0 | I49: =H49 -> 0 | J49: =I49 -> 0
B50: Operating Lease Liabilities | C50: 12460 | D50: 11691 | E50: 12744 | F50: =E50 -> 12744 | G50: =F50 -> 12744 | H50: =G50 -> 12744 | I50: =H50 -> 12744 | J50: =I50 -> 12744
B51: Other Long-term Liabilities | C51: 1616 | D51: 4694 | E51: 8449 | F51: =E51 -> 8449 | G51: =F51 -> 8449 | H51: =G51 -> 8449 | I51: =H51 -> 8449 | J51: =I51 -> 8449
B53: Total Non-Current Liabilities | C53: =SUM(C46:C51) -> 37199 | D53: =SUM(D46:D51) -> 36050 | E53: =SUM(E46:E51) -> 77271 | F53: =SUM(F46:F51) -> 77271 | G53: =SUM(G46:G51) -> 77271 | H53: =SUM(H46:H51) -> 77271 | I53: =SUM(I46:I51) -> 77271 | J53: =SUM(J46:J51) -> 77271
B55: Total Liabilities | C55: =SUM(C43+C53) -> 119013 | D55: =SUM(D43+D53) -> 125172 | E55: =SUM(E43+E53) -> 180016 | F55: =SUM(F43+F53) -> 181592.99 | G55: =SUM(G43+G53) -> 183384 | H55: =SUM(H43+H53) -> 185252.16 | I55: =SUM(I43+I53) -> 187170.14 | J55: =SUM(J43+J53) -> 189105.55
...

Sheet Cash Flow Statement
B2: Cash Flow Statement
B4: ($ in millions) | C4: Historical | F4: Forecast
C5: FY2023A | D5: FY2024A | E5: FY2025A | F5: FY2026E | G5: FY2027E | H5: FY2028E | I5: FY2029E | J5: FY2030E
B6: Net Income | C6: ='Income Statement'!C36 -> 68767 | D6: ='Income Statement'!D36 -> 100164 | E6: ='Income Statement'!E36 -> 137031 | F6: ='Income Statement'!F36 -> 126686.18 | G6: ='Income Statement'!G36 -> 145068.5 | H6: ='Income Statement'!H36 -> 164310.75 | I6: ='Income Statement'!I36 -> 184572.91 | J6: ='Income Statement'!J36 -> 204992.81
B8: Operating Activities:
B10: Adjustments:
B11: Depreciation, Amortization, and other | C11: 11946 | D11: 15311 | E11: 21136 | F11: ='Income Statement'!F11*Assumptions!E20 -> 27553.982 | G11: ='Income Statement'!G11*Assumptions!F20 -> 33730.667 | H11: ='Income Statement'!H11*Assumptions!G20 -> 40684.373 | I11: ='Income Statement'!I11*Assumptions!H20 -> 46449.93 | J11: ='Income Statement'!J11*Assumptions!I20 -> 52514.227
B12: Stock-based Compensation Expense | C12: 22460 | D12: 22785 | E12: 24953 | F12: 0 | G12: =F12 -> 0 | H12: =G12 -> 0 | I12: =H12 -> 0 | J12: =I12 -> 0
B13: Investment and Derivatives Gains/Losses | C13: 823 | D13: 2671 | E13: 24620 | F13: 0 | G13: =F13 -> 0 | H13: =G13 -> 0 | I13: =H13 -> 0 | J13: =I13 -> 0
B14: Deferred Income Taxes | C14: 7763 | D14: 5257 | E14: 8348 | F14: 0 | G14: =F14 -> 0 | H14: =G14 -> 0 | I14: =H14 -> 0 | J14: =I14 -> 0
B16: Changes in Operating Assets and Liabilities:
B17: Accounts Receivable | C17: 7833 | D17: 5891 | E17: 8779 | F17: =-('Balance Sheet'!F14-'Balance Sheet'!E14) -> -8754.3542 | G17: =-('Balance Sheet'!G14-'Balance Sheet'!F14) -> -9313.2461 | H17: =-('Balance Sheet'!H14-'Balance Sheet'!G14) -> -9714.432 | I17: =-('Balance Sheet'!I14-'Balance Sheet'!H14) -> -9973.4836 | J17: =-('Balance Sheet'!J14-'Balance Sheet'!I14) -> -10064.152
B18: Inventories | C18: 0 | D18: 0 | E18: 0 | F18: =-('Balance Sheet'!F15-'Balance Sheet'!E15) -> 0 | G18: =-('Balance Sheet'!G15-'Balance Sheet'!F15) -> 0 | H18: =-('Balance Sheet'!H15-'Balance Sheet'!G15) -> 0 | I18: =-('Balance Sheet'!I15-'Balance Sheet'!H15) -> 0 | J18: =-('Balance Sheet'!J15-'Balance Sheet'!I15) -> 0
B19: Other Current Assets | C19: 2143 | D19: 1397 | E19: 4542 | F19: =-('Balance Sheet'!F16-'Balance Sheet'!E16) -> 0 | G19: =-('Balance Sheet'!G16-'Balance Sheet'!F16) -> 0 | H19: =-('Balance Sheet'!H16-'Balance Sheet'!G16) -> 0 | I19: =-('Balance Sheet'!I16-'Balance Sheet'!H16) -> 0 | J19: =-('Balance Sheet'!J16-'Balance Sheet'!I16) -> 0
B20: Other Long-Term Assets | C20: 0 | D20: 0 | E20: 0 | F20: =-('Balance Sheet'!F26-'Balance Sheet'!E26) -> 0 | G20: =-('Balance Sheet'!G26-'Balance Sheet'!F26) -> 0 | H20: =-('Balance Sheet'!H26-'Balance Sheet'!G26) -> 0 | I20: =-('Balance Sheet'!I26-'Balance Sheet'!H26) -> 0 | J20: =-('Balance Sheet'!J26-'Balance Sheet'!I26) -> 0
B21: Accounts Payable | C21: 664 | D21: 359 | E21: 907 | F21: ='Balance Sheet'!F35-'Balance Sheet'!E35 -> 1576.9912 | G21: ='Balance Sheet'!G35-'Balance Sheet'!F35 -> 1791.0089 | H21: ='Balance Sheet'!H35-'Balance Sheet'!G35 -> 1868.16 | I21: ='Balance Sheet'!I35-'Balance Sheet'!H35 -> 1917.9776 | J21: ='Balance Sheet'!J35-'Balance Sheet'!I35 -> 1935.4138
B22: Unearned Revenue | C22: 525 | D22: 1043 | E22: 2420 | F22: =('Balance Sheet'!F40+'Balance Sheet'!F48)-('Balance Sheet'!E40+'Balance Sheet'!E48) -> 0 | G22: =('Balance Sheet'!G40+'Balance Sheet'!G48)-('Balance Sheet'!F40+'Balance Sheet'!F48) -> 0 | H22: =('Balance Sheet'!H40+'Balance Sheet'!H48)-('Balance Sheet'!G40+'Balance Sheet'!G48) -> 0 | I22: =('Balance Sheet'!I40+'Balance Sheet'!I48)-('Balance Sheet'!H40+'Balance Sheet'!H48) -> 0 | J22: =('Balance Sheet'!J40+'Balance Sheet'!J48)-('Balance Sheet'!I40+'Balance Sheet'!I48) -> 0
B23: Income Taxes | C23: 523 | D23: 2418 | E23: 3226 | F23: =('Balance Sheet'!F39+'Balance Sheet'!F47)-('Balance Sheet'!E39+'Balance Sheet'!E47) -> 0 | G23: =('Balance Sheet'!G39+'Balance Sheet'!G47)-('Balance Sheet'!F39+'Balance Sheet'!F47) -> 0 | H23: =('Balance Sheet'!H39+'Balance Sheet'!H47)-('Balance Sheet'!G39+'Balance Sheet'!G47) -> 0 | I23: =('Balance Sheet'!I39+'Balance Sheet'!I47)-('Balance Sheet'!H39+'Balance Sheet'!H47) -> 0 | J23: =('Balance Sheet'!J39+'Balance Sheet'!J47)-('Balance Sheet'!I39+'Balance Sheet'!I47) -> 0
B24: Other Current Liabilities | C24: 4419 | D24: 2220 | E24: 13838 | F24: ='Balance Sheet'!F41-'Balance Sheet'!E41 -> 0 | G24: ='Balance Sheet'!G41-'Balance Sheet'!F41 -> 0 | H24: ='Balance Sheet'!H41-'Balance Sheet'!G41 -> 0 | I24: ='Balance Sheet'!I41-'Balance Sheet'!H41 -> 0 | J24: ='Balance Sheet'!J41-'Balance Sheet'!I41 -> 0
B25: Other Long-Term Liabilities | C25: 42647 | D25: 65947 | E25: 51944 | F25: ='Balance Sheet'!F51-'Balance Sheet'!E51 -> 0 | G25: ='Balance Sheet'!G51-'Balance Sheet'!F51 -> 0 | H25: ='Balance Sheet'!H51-'Balance Sheet'!G51 -> 0 | I25: ='Balance Sheet'!I51-'Balance Sheet'!H51 -> 0 | J25: ='Balance Sheet'!J51-'Balance Sheet'!I51 -> 0
B27: Net Cash from Operating Activities | C27: =SUM(C6:C25) -> 170513 | D27: =SUM(D6:D25) -> 225463 | E27: =SUM(E6:E25) -> 301744 | F27: =F6+SUM(F11:F25) -> 147062.8 | G27: =G6+SUM(G11:G25) -> 171276.93 | H27: =H6+SUM(H11:H25) -> 197148.85 | I27: =I6+SUM(I11:I25) -> 222967.33 | J27: =J6+SUM(J11:J25) -> 249378.3
B29: Investing Activities:
B30: Additions to Property and Equipment | C30: -32251 | D30: -52535 | E30: -91447 | F30: =-'Income Statement'!F11*Assumptions!E19 -> -137769.91 | G30: =-'Income Statement'!G11*Assumptions!F19 -> -140112 | H30: =-'Income Statement'!H11*Assumptions!G19 -> -139489.28 | I30: =-'Income Statement'!I11*Assumptions!H19 -> -141930.34 | J30: =-'Income Statement'!J11*Assumptions!I19 -> -141930.34
B31: Acquisitions, Net | C31: -495 | D31: -2931 | E31: -1592 | F31: 0 | G31: 0 | H31: 0 | I31: 0 | J31: 0
B32: Purchases of Investments | C32: -77858 | D32: -86679 | E32: -103773 | F32: =-'Income Statement'!F11*Assumptions!E21 -> -101031.27 | G32: =-'Income Statement'!G11*Assumptions!F21 -> -103786.67 | H32: =-'Income Statement'!H11*Assumptions!G21 -> -104616.96 | I32: =-'Income Statement'!I11*Assumptions!H21 -> -103222.07 | J32: =-'Income Statement'!J11*Assumptions!I21 -> -106447.76
B33: Maturities of Investments | C33: 86672 | D33: 103428 | E33: 83240 | F33: 0 | G33: 0 | H33: 0 | I33: 0 | J33: 0
B34: Sales of Investments | C34: 0 | D34: 0 | E34: 0 | F34: 0 | G34: 0 | H34: 0 | I34: 0 | J34: 0
B35: Other, Net | C35: -3131 | D35: -6819 | E35: -6719 | F35: 0 | G35: 0 | H35: 0 | I35: 0 | J35: 0
B37: Net Cash Used in Investing Activities | C37: =SUM(C30:C35) -> -27063 | D37: =SUM(D30:D35) -> -45536 | E37: =SUM(E30:E35) -> -120291 | F37: =SUM(F30:F35) -> -238801.18 | G37: =SUM(G30:G35) -> -243898.67 | H37: =SUM(H30:H35) -> -244106.24 | I37: =SUM(I30:I35) -> -245152.41 | J37: =SUM(J30:J35) -> -248378.1
B39: Financing Activities:
B40: Short-Term Debt Issued/(Repaid), Net | C40: 0 | D40: 0 | E40: 0 | F40: 0 | G40: 0 | H40: 0 | I40: 0 | J40: 0
B41: Long-Term Debt Issued | C41: 10790 | D41: 13589 | E41: 64564 | F41: 0 | G41: 0 | H41: 0 | I41: 0 | J41: 0
B42: Long-Term Debt Repaid | C42: -11550 | D42: -12701 | E42: -32427 | F42: 0 | G42: 0 | H42: 0 | I42: 0 | J42: 0
B43: Common Stock Issued | C43: -9837 | D43: -12190 | E43: -14167 | F43: 0 | G43: 0 | H43: 0 | I43: 0 | J43: 0
B44: Share Repurchases | C44: -61504 | D44: -62222 | E44: -45709 | F44: 0 | G44: 0 | H44: 0 | I44: 0 | J44: 0
B45: Dividends Paid | C45: 0 | D45: -7363 | E45: -10049 | F45: =E45*(1+Assumptions!E29) -> -11053.9 | G45: =F45*(1+Assumptions!F29) -> -12159.29 | H45: =G45*(1+Assumptions!G29) -> -13253.626 | I45: =H45*(1+Assumptions!H29) -> -14446.452 | J45: =I45*(1+Assumptions!I29) -> -15602.169
B46: Other, Net | C46: 8 | D46: 1154 | E46: 400 | F46: 0 | G46: 0 | H46: 0 | I46: 0 | J46: 0
B48: Net Cash Used in Financing Activities | C48: =SUM(C40:C46) -> -72093 | D48: =SUM(D40:D46) -> -79733 | E48: =SUM(E40:E46) -> -37388 | F48: =SUM(F40:F46) -> -11053.9 | G48: =SUM(G40:G46) -> -12159.29 | H48: =SUM(H40:H46) -> -13253.626 | I48: =SUM(I40:I46) -> -14446.452 | J48: =SUM(J40:J46) -> -15602.169
B50: FX Effect on Cash and Cash Equivalents | C50: 421 | D50: 612 | E50: 208 | F50: 0 | G50: 0 | H50: 0 | I50: 0 | J50: 0
B52: Net Change in Cash and Cash Equivalents | C52: =SUM(C27+C37+C48+C50) -> 71778 | D52: =SUM(D27+D37+D48+D50) -> 100806 | E52: =SUM(E27+E37+E48+E50) -> 144273 | F52: =F27+F37+F48+F50 -> -102792.28 | G52: =G27+G37+G48+G50 -> -84781.031 | H52: =H27+H37+H48+H50 -> -60211.013 | I52: =I27+I37+I48+I50 -> -36631.532 | J52: =J27+J37+J48+J50 -> -14601.967
...

Sheet Supporting Schedules
B2: Supporting Schedules
B4: PP&E Schedule
B5: PP&E Schedule | C5: FY2025A | D5: FY2026E | E5: FY2027E | F5: FY2028E | G5: FY2029E | H5: FY2030E
B6: Beginning PP&E | C6: ='Balance Sheet'!D21 -> 171036 | D6: ='Balance Sheet'!E21 -> 246597 | E6: ='Balance Sheet'!F21 -> 356812.93 | F6: ='Balance Sheet'!G21 -> 463194.26 | G6: ='Balance Sheet'!H21 -> 561999.17 | H6: ='Balance Sheet'!I21 -> 657479.58
B7: + CapEx | C7: =-'Cash Flow Statement'!E30 -> 91447 | D7: =-'Cash Flow Statement'!F30 -> 137769.91 | E7: =-'Cash Flow Statement'!G30 -> 140112 | F7: =-'Cash Flow Statement'!H30 -> 139489.28 | G7: =-'Cash Flow Statement'!I30 -> 141930.34 | H7: =-'Cash Flow Statement'!J30 -> 141930.34
B8: - Depreciation | C8: ='Cash Flow Statement'!E11 -> 21136 | D8: ='Cash Flow Statement'!F11 -> 27553.982 | E8: ='Cash Flow Statement'!G11 -> 33730.667 | F8: ='Cash Flow Statement'!H11 -> 40684.373 | G8: ='Cash Flow Statement'!I11 -> 46449.93 | H8: ='Cash Flow Statement'!J11 -> 52514.227
B9: + Other PP&E movements | C9: 38977 | D9: 0 | E9: 0 | F9: 0 | G9: 0 | H9: 0
B10: Ending PP&E | C10: =C6+C7-C8+C9 -> 280324 | D10: =D6+D7-D8+D9 -> 356812.93 | E10: =E6+E7-E8+E9 -> 463194.26 | F10: =F6+F7-F8+F9 -> 561999.17 | G10: =G6+G7-G8+G9 -> 657479.58 | H10: =H6+H7-H8+H9 -> 746895.7
B12: Working Capital Schedule
B14: Accounts Receivable | C14: FY2025A | D14: FY2026E | E14: FY2027E | F14: FY2028E | G14: FY2029E | H14: FY2030E
B15: Revenue | C15: ='Income Statement'!E11 -> 402836 | D15: ='Income Statement'!F11 -> 459233.04 | E15: ='Income Statement'!G11 -> 518933.34 | F15: ='Income Statement'!H11 -> 581205.34 | G15: ='Income Statement'!I11 -> 645137.92 | H15: ='Income Statement'!J11 -> 709651.71
B16: AR % Revenue | C16: ='Balance Sheet'!E14/C15 -> 0.15610819 | D16: =Assumptions!E24 -> 0.156 | E16: =Assumptions!F24 -> 0.156 | F16: =Assumptions!G24 -> 0.156 | G16: =Assumptions!H24 -> 0.156 | H16: =Assumptions!I24 -> 0.156
B17: Ending AR | C17: =C15*C16 -> 62886 | D17: =D15*D16 -> 71640.354 | E17: =E15*E16 -> 80953.6 | F17: =F15*F16 -> 90668.032 | G17: =G15*G16 -> 100641.52 | H17: =H15*H16 -> 110705.67
B19: Inventory | C19: FY2025A | D19: FY2026E | E19: FY2027E | F19: FY2028E | G19: FY2029E | H19: FY2030E
B20: Revenue | C20: ='Income Statement'!E11 -> 402836 | D20: ='Income Statement'!F11 -> 459233.04 | E20: ='Income Statement'!G11 -> 518933.34 | F20: ='Income Statement'!H11 -> 581205.34 | G20: ='Income Statement'!I11 -> 645137.92 | H20: ='Income Statement'!J11 -> 709651.71
B21: Inventory % Revenue | C21: ='Balance Sheet'!E15/C20 -> 0 | D21: =Assumptions!E25 -> 0 | E21: =Assumptions!F25 -> 0 | F21: =Assumptions!G25 -> 0 | G21: =Assumptions!H25 -> 0 | H21: =Assumptions!I25 -> 0
B22: Ending Inventory | C22: =C20*C21 -> 0 | D22: =D20*D21 -> 0 | E22: =E20*E21 -> 0 | F22: =F20*F21 -> 0 | G22: =G20*G21 -> 0 | H22: =H20*H21 -> 0
B24: Accounts Payable | C24: FY2025A | D24: FY2026E | E24: FY2027E | F24: FY2028E | G24: FY2029E | H24: FY2030E
B25: Revenue | C25: ='Income Statement'!E11 -> 402836 | D25: ='Income Statement'!F11 -> 459233.04 | E25: ='Income Statement'!G11 -> 518933.34 | F25: ='Income Statement'!H11 -> 581205.34 | G25: ='Income Statement'!I11 -> 645137.92 | H25: ='Income Statement'!J11 -> 709651.71
B26: AP % Revenue | C26: ='Balance Sheet'!E35/C25 -> 0.030285277 | D26: =Assumptions!E26 -> 0.03 | E26: =Assumptions!F26 -> 0.03 | F26: =Assumptions!G26 -> 0.03 | G26: =Assumptions!H26 -> 0.03 | H26: =Assumptions!I26 -> 0.03
B27: Ending AP | C27: =C25*C26 -> 12200 | D27: =D25*D26 -> 13776.991 | E27: =E25*E26 -> 15568 | F27: =F25*F26 -> 17436.16 | G27: =G25*G26 -> 19354.138 | H27: =H25*H26 -> 21289.551
B29: Net Working Capital | C29: =C17+C22-C27 -> 50686 | D29: =D17+D22-D27 -> 57863.363 | E29: =E17+E22-E27 -> 65385.6 | F29: =F17+F22-F27 -> 73231.872 | G29: =G17+G22-G27 -> 81287.378 | H29: =H17+H22-H27 -> 89416.116
B30: Change in Net Working Capital | D30: =D29-C29 -> 7177.363 | E30: =E29-D29 -> 7522.2372 | F30: =F29-E29 -> 7846.272 | G30: =G29-F29 -> 8055.5059 | H30: =H29-G29 -> 8128.7378
B32: Investment Schedule
B34: Short-term Investments | C34: FY2025A | D34: FY2026E | E34: FY2027E | F34: FY2028E | G34: FY2029E | H34: FY2030E
B35: Beginning Balance | C35: ='Balance Sheet'!D11 -> 72191 | D35: =C40 -> 96135 | E35: =D40 -> 197166.27 | F35: =E40 -> 300952.94 | G35: =F40 -> 405569.9 | H35: =G40 -> 508791.96
B36: + Purchases | C36: =-'Cash Flow Statement'!E32 -> 103773 | D36: =-'Cash Flow Statement'!F32 -> 101031.27 | E36: =-'Cash Flow Statement'!G32 -> 103786.67 | F36: =-'Cash Flow Statement'!H32 -> 104616.96 | G36: =-'Cash Flow Statement'!I32 -> 103222.07 | H36: =-'Cash Flow Statement'!J32 -> 106447.76
B37: - Maturities | C37: 16079 | D37: 0 | E37: 0 | F37: 0 | G37: 0 | H37: 0
B38: - Sales | C38: ='Cash Flow Statement'!E34 -> 0 | D38: 0 | E38: 0 | F38: 0 | G38: 0 | H38: 0
B39: + Other Movements | C39: ='Balance Sheet'!E11-C35-C36+C37+C38 -> -63750 | D39: 0 | E39: 0 | F39: 0 | G39: 0 | H39: 0
B40: Ending Balance | C40: =C35+C36-C37-C38+C39 -> 96135 | D40: =D35+D36-D37-D38+D39 -> 197166.27 | E40: =E35+E36-E37-E38+E39 -> 300952.94 | F40: =F35+F36-F37-F38+F39 -> 405569.9 | G40: =G35+G36-G37-G38+G39 -> 508791.96 | H40: =H35+H36-H37-H38+H39 -> 615239.72
B42: Depreciation Schedule
B44: Depreciation | C44: =C42*C43 -> 0 | D44: =D42*D43 -> 0 | E44: =E42*E43 -> 0 | F44: =F42*F43 -> 0 | G44: =G42*G43 -> 0 | H44: =H42*H43 -> 0
B45: Revenue | C45: ='Income Statement'!E11 -> 402836 | D45: ='Income Statement'!F11 -> 459233.04 | E45: ='Income Statement'!G11 -> 518933.34 | F45: ='Income Statement'!H11 -> 581205.34 | G45: ='Income Statement'!I11 -> 645137.92 | H45: ='Income Statement'!J11 -> 709651.71
B46: Depreciation % Revenue | C46: ='Cash Flow Statement'!E11/C45 -> 0.052468002 | D46: =Assumptions!E20 -> 0.06 | E46: =Assumptions!F20 -> 0.065 | F46: =Assumptions!G20 -> 0.07 | G46: =Assumptions!H20 -> 0.072 | H46: =Assumptions!I20 -> 0.074
B47: Depreciation Expense | C47: =C45*C46 -> 21136 | D47: =D45*D46 -> 27553.982 | E47: =E45*E46 -> 33730.667 | F47: =F45*F46 -> 40684.373 | G47: =G45*G46 -> 46449.93 | H47: =H45*H46 -> 52514.227

Sheet DCF Valuation
B2: DCF Valuation
B4: Unlevered Free Cash Flow | I4: DCF Assumptions
B5: ($ in millions, except per-share data) | C5: FY2026E | D5: FY2027E | E5: FY2028E | F5: FY2029E | G5: FY2030E | I5: Risk-Free Rate % | J5: 0.0461
B6: Revenue | C6: ='Income Statement'!F11 -> 459233.04 | D6: ='Income Statement'!G11 -> 518933.34 | E6: ='Income Statement'!H11 -> 581205.34 | F6: ='Income Statement'!I11 -> 645137.92 | G6: ='Income Statement'!J11 -> 709651.71 | I6: Beta | J6: 1.1
B7: Revenue Growth % | C7: ='Income Statement'!F11/'Income Statement'!E11-1 -> 0.14 | D7: ='Income Statement'!G11/'Income Statement'!F11-1 -> 0.13 | E7: ='Income Statement'!H11/'Income Statement'!G11-1 -> 0.12 | F7: ='Income Statement'!I11/'Income Statement'!H11-1 -> 0.11 | G7: ='Income Statement'!J11/'Income Statement'!I11-1 -> 0.1 | I7: Equity Risk Premium % | J7: 0.048
I8: Cost of Equity % | J8: =J5+(J6*J7) -> 0.0989
B9: EBIT/Operating Income | C9: ='Income Statement'!F28 -> 146495.34 | D9: ='Income Statement'!G28 -> 168912.8 | E9: ='Income Statement'!H28 -> 192378.97 | F9: ='Income Statement'!I28 -> 217088.91 | G9: ='Income Statement'!J28 -> 241991.23
B10: EBIT Margin % | C10: ='Income Statement'!F28/'Income Statement'!F11 -> 0.319 | D10: ='Income Statement'!G28/'Income Statement'!G11 -> 0.3255 | E10: ='Income Statement'!H28/'Income Statement'!H11 -> 0.331 | F10: ='Income Statement'!I28/'Income Statement'!I11 -> 0.3365 | G10: ='Income Statement'!J28/'Income Statement'!J11 -> 0.341 | I10: Pre-tax Cost of Debt Assumption | J10: 0.049
I11: Tax Rate | J11: =Assumptions!E16 -> 0.18
B12: Taxes on EBIT | C12: ='Income Statement'!F28*Assumptions!E16 -> 26369.161 | D12: ='Income Statement'!G28*Assumptions!F16 -> 30404.304 | E12: ='Income Statement'!H28*Assumptions!G16 -> 34628.214 | F12: ='Income Statement'!I28*Assumptions!H16 -> 39076.004 | G12: ='Income Statement'!J28*Assumptions!I16 -> 43558.422 | I12: After-Tax Cost of Debt | J12: =J10*(1-J11) -> 0.04018
B14: Net Operating Profit After Tax | C14: =C9-C12 -> 120126.18 | D14: =D9-D12 -> 138508.5 | E14: =E9-E12 -> 157750.75 | F14: =F9-F12 -> 178012.91 | G14: =G9-G12 -> 198432.81 | I14: Market Value of Equity ($m) | J14: =J19*'Income Statement'!E44 -> 3916168.3
I15: Market Value of Debt ($m) | J15: ='Balance Sheet'!E36+'Balance Sheet'!E37+'Balance Sheet'!E46 -> 46547
B16: Depreciation & Amortization | C16: ='Cash Flow Statement'!F11 -> 27553.982 | D16: ='Cash Flow Statement'!G11 -> 33730.667 | E16: ='Cash Flow Statement'!H11 -> 40684.373 | F16: ='Cash Flow Statement'!I11 -> 46449.93 | G16: ='Cash Flow Statement'!J11 -> 52514.227 | I16: Total Capital ($m) | J16: =J14+J15 -> 3962715.3
B17: Capital Expenditures | C17: ='Cash Flow Statement'!F30 -> -137769.91 | D17: ='Cash Flow Statement'!G30 -> -140112 | E17: ='Cash Flow Statement'!H30 -> -139489.28 | F17: ='Cash Flow Statement'!I30 -> -141930.34 | G17: ='Cash Flow Statement'!J30 -> -141930.34 | I17: Weight of Equity | J17: =J14/J16 -> 0.98825376
B18: Change in Net Working Capital | C18: ='Supporting Schedules'!D30 -> 7177.363 | D18: ='Supporting Schedules'!E30 -> 7522.2372 | E18: ='Supporting Schedules'!F30 -> 7846.272 | F18: ='Supporting Schedules'!G30 -> 8055.5059 | G18: ='Supporting Schedules'!H30 -> 8128.7378 | I18: Weight of Debt | J18: =J15/J16 -> 0.011746239
I19: Current Share Price ($) | J19: 320.21
B20: Unlevered Free Cash Flow (UFCF) | C20: =C14+C16+C17-C18 -> 2732.886 | D20: =D14+D16+D17-D18 -> 24604.926 | E20: =E14+E16+E17-E18 -> 51099.573 | F20: =F14+F16+F17-F18 -> 74476.988 | G20: =G14+G16+G17-G18 -> 100887.96 | I20: Valuation Date | J20: 46321
I21: WACC | J21: =J17*J8+J18*J12 -> 0.098210261
B22: UFCF Growth % | D22: =D20/C20-1 -> 8.0032756 | E22: =E20/D20-1 -> 1.0768026 | F22: =F20/E20-1 -> 0.45748749 | G22: =G20/F20-1 -> 0.3546192 | I22: Terminal Growth Rate | J22: 0.025
B24: Present Value of UFCF | I24: Key Outputs
B25: ($ in millions) | C25: FY2026E | D25: FY2027E | E25: FY2028E | F25: FY2029E | G25: FY2030E | I25: Diluted Shares Outstanding (m) | J25: ='Income Statement'!E44 -> 12230
B26: Discount Period | C26: 1 | D26: 2 | E26: 3 | F26: 4 | G26: 5 | I26: Implied Share Price ($/share) | J26: =C60 -> 93.241955
B27: UFCF | C27: =C20 -> 2732.886 | D27: =D20 -> 24604.926 | E27: =E20 -> 51099.573 | F27: =F20 -> 74476.988 | G27: =G20 -> 100887.96 | I27: Current Share Price ($/share) | J27: =J19 -> 320.21
B28: Discount Factor @ WACC | C28: =1/(1+$J$21)^C26 -> 0.91057244 | D28: =1/(1+$J$21)^D26 -> 0.82914217 | E28: =1/(1+$J$21)^E26 -> 0.75499401 | F28: =1/(1+$J$21)^F26 -> 0.68747674 | G28: =1/(1+$J$21)^G26 -> 0.62599738 | I28: Upside/ (Downside) | J28: =C63 -> -0.70880998
B30: PV of UFCF | C30: =C27*C28 -> 2488.4906 | D30: =D27*D28 -> 20400.981 | E30: =E27*E28 -> 38579.872 | F30: =F27*F28 -> 51201.198 | G30: =G27*G28 -> 63155.598
B32: Total PV of UFCF | C32: =SUM(C30:G30) -> 175826.14
B34: Terminal Value
B35: FY2030E UFCF | C35: =G20 -> 100887.96
B36: Terminal Growth Rate | C36: =J22 -> 0.025
B37: FY2031E UFCF | C37: =C35*(1+C36) -> 103410.16
B38: WACC | C38: =J21 -> 0.098210261
B40: Terminal Value | C40: =C37/(C38-C36) -> 1412509.1
B42: Discount Factor | C42: =G28 -> 0.62599738
B44: PV of Terminal Value | C44: =C40*C42 -> 884226.98
B46: Valuation Summary
B47: ($ in millions, except per-share data)
B49: Total PV of UFCF | C49: =C32 -> 175826.14
B50: PV of Terminal Value | C50: =C44 -> 884226.98
B52: Enterprise Value | C52: =SUM(C49:C50) -> 1060053.1
B54: Cash and Short-Term Investments | C54: ='Balance Sheet'!E13 -> 126843
...

Sheet Sensitivity Analysis
B2: Sensitivity Analysis
B4: Implied Share Price Sensitivity ($/share)
B5: WACC ↓ / Terminal Growth → | C5: =$E$5-1% -> 0.015 | D5: =$E$5-0.5% -> 0.02 | E5: ='DCF Valuation'!$J$22 -> 0.025 | F5: =$E$5+0.5% -> 0.03 | G5: =$E$5+1% -> 0.035
B6: =$B$8-1% -> 0.088210261 | C6: =IF($B6<=C$5,"n/m",(SUMPRODUCT('DCF Valuation'!$C$27:$G$27,1/(1+$B6)^'DCF Valuation'!$C$26:$G$26)+('DCF Valuation'!$G$27*(1+C$5)/($B6-C$5))/(1+$B6)^'DCF Valuation'!$G$26+'DCF Valuation'!$C$54-'DCF Valuation'!$C$55)/'DCF Valuation'!$C$59) -> 96.405285 | D6: =IF($B6<=D$5,"n/m",(SUMPRODUCT('DCF Valuation'!$C$27:$G$27,1/(1+$B6)^'DCF Valuation'!$C$26:$G$26)+('DCF Valuation'!$G$27*(1+D$5)/($B6-D$5))/(1+$B6)^'DCF Valuation'!$G$26+'DCF Valuation'!$C$54-'DCF Valuation'!$C$55)/'DCF Valuation'!$C$59) -> 102.29521 | E6: =IF($B6<=E$5,"n/m",(SUMPRODUCT('DCF Valuation'!$C$27:$G$27,1/(1+$B6)^'DCF Valuation'!$C$26:$G$26)+('DCF Valuation'!$G$27*(1+E$5)/($B6-E$5))/(1+$B6)^'DCF Valuation'!$G$26+'DCF Valuation'!$C$54-'DCF Valuation'!$C$55)/'DCF Valuation'!$C$59) -> 109.11694 | F6: =IF($B6<=F$5,"n/m",(SUMPRODUCT('DCF Valuation'!$C$27:$G$27,1/(1+$B6)^'DCF Valuation'!$C$26:$G$26)+('DCF Valuation'!$G$27*(1+F$5)/($B6-F$5))/(1+$B6)^'DCF Valuation'!$G$26+'DCF Valuation'!$C$54-'DCF Valuation'!$C$55)/'DCF Valuation'!$C$59) -> 117.11058 | G6: =IF($B6<=G$5,"n/m",(SUMPRODUCT('DCF Valuation'!$C$27:$G$27,1/(1+$B6)^'DCF Valuation'!$C$26:$G$26)+('DCF Valuation'!$G$27*(1+G$5)/($B6-G$5))/(1+$B6)^'DCF Valuation'!$G$26+'DCF Valuation'!$C$54-'DCF Valuation'!$C$55)/'DCF Valuation'!$C$59) -> 126.60649
B7: =$B$8-0.5% -> 0.093210261 | C7: =IF($B7<=C$5,"n/m",(SUMPRODUCT('DCF Valuation'!$C$27:$G$27,1/(1+$B7)^'DCF Valuation'!$C$26:$G$26)+('DCF Valuation'!$G$27*(1+C$5)/($B7-C$5))/(1+$B7)^'DCF Valuation'!$G$26+'DCF Valuation'!$C$54-'DCF Valuation'!$C$55)/'DCF Valuation'!$C$59) -> 89.762209 | D7: =IF($B7<=D$5,"n/m",(SUMPRODUCT('DCF Valuation'!$C$27:$G$27,1/(1+$B7)^'DCF Valuation'!$C$26:$G$26)+('DCF Valuation'!$G$27*(1+D$5)/($B7-D$5))/(1+$B7)^'DCF Valuation'!$G$26+'DCF Valuation'!$C$54-'DCF Valuation'!$C$55)/'DCF Valuation'!$C$59) -> 94.805713 | E7: =IF($B7<=E$5,"n/m",(SUMPRODUCT('DCF Valuation'!$C$27:$G$27,1/(1+$B7)^'DCF Valuation'!$C$26:$G$26)+('DCF Valuation'!$G$27*(1+E$5)/($B7-E$5))/(1+$B7)^'DCF Valuation'!$G$26+'DCF Valuation'!$C$54-'DCF Valuation'!$C$55)/'DCF Valuation'!$C$59) -> 100.58862 | F7: =IF($B7<=F$5,"n/m",(SUMPRODUCT('DCF Valuation'!$C$27:$G$27,1/(1+$B7)^'DCF Valuation'!$C$26:$G$26)+('DCF Valuation'!$G$27*(1+F$5)/($B7-F$5))/(1+$B7)^'DCF Valuation'!$G$26+'DCF Valuation'!$C$54-'DCF Valuation'!$C$55)/'DCF Valuation'!$C$59) -> 107.2864 | G7: =IF($B7<=G$5,"n/m",(SUMPRODUCT('DCF Valuation'!$C$27:$G$27,1/(1+$B7)^'DCF Valuation'!$C$26:$G$26)+('DCF Valuation'!$G$27*(1+G$5)/($B7-G$5))/(1+$B7)^'DCF Valuation'!$G$26+'DCF Valuation'!$C$54-'DCF Valuation'!$C$55)/'DCF Valuation'!$C$59) -> 115.1348
B8: ='DCF Valuation'!$J$21 -> 0.098210261 | C8: =IF($B8<=C$5,"n/m",(SUMPRODUCT('DCF Valuation'!$C$27:$G$27,1/(1+$B8)^'DCF Valuation'!$C$26:$G$26)+('DCF Valuation'!$G$27*(1+C$5)/($B8-C$5))/(1+$B8)^'DCF Valuation'!$G$26+'DCF Valuation'!$C$54-'DCF Valuation'!$C$55)/'DCF Valuation'!$C$59) -> 83.932548 | D8: =IF($B8<=D$5,"n/m",(SUMPRODUCT('DCF Valuation'!$C$27:$G$27,1/(1+$B8)^'DCF Valuation'!$C$26:$G$26)+('DCF Valuation'!$G$27*(1+D$5)/($B8-D$5))/(1+$B8)^'DCF Valuation'!$G$26+'DCF Valuation'!$C$54-'DCF Valuation'!$C$55)/'DCF Valuation'!$C$59) -> 88.289675 | E8: =IF($B8<=E$5,"n/m",(SUMPRODUCT('DCF Valuation'!$C$27:$G$27,1/(1+$B8)^'DCF Valuation'!$C$26:$G$26)+('DCF Valuation'!$G$27*(1+E$5)/($B8-E$5))/(1+$B8)^'DCF Valuation'!$G$26+'DCF Valuation'!$C$54-'DCF Valuation'!$C$55)/'DCF Valuation'!$C$59) -> 93.241955 | F8: =IF($B8<=F$5,"n/m",(SUMPRODUCT('DCF Valuation'!$C$27:$G$27,1/(1+$B8)^'DCF Valuation'!$C$26:$G$26)+('DCF Valuation'!$G$27*(1+F$5)/($B8-F$5))/(1+$B8)^'DCF Valuation'!$G$26+'DCF Valuation'!$C$54-'DCF Valuation'!$C$55)/'DCF Valuation'!$C$59) -> 98.920267 | G8: =IF($B8<=G$5,"n/m",(SUMPRODUCT('DCF Valuation'!$C$27:$G$27,1/(1+$B8)^'DCF Valuation'!$C$26:$G$26)+('DCF Valuation'!$G$27*(1+G$5)/($B8-G$5))/(1+$B8)^'DCF Valuation'!$G$26+'DCF Valuation'!$C$54-'DCF Valuation'!$C$55)/'DCF Valuation'!$C$59) -> 105.4969
B9: =$B$8+0.5% -> 0.10321026 | C9: =IF($B9<=C$5,"n/m",(SUMPRODUCT('DCF Valuation'!$C$27:$G$27,1/(1+$B9)^'DCF Valuation'!$C$26:$G$26)+('DCF Valuation'!$G$27*(1+C$5)/($B9-C$5))/(1+$B9)^'DCF Valuation'!$G$26+'DCF Valuation'!$C$54-'DCF Valuation'!$C$55)/'DCF Valuation'!$C$59) -> 78.77765 | D9: =IF($B9<=D$5,"n/m",(SUMPRODUCT('DCF Valuation'!$C$27:$G$27,1/(1+$B9)^'DCF Valuation'!$C$26:$G$26)+('DCF Valuation'!$G$27*(1+D$5)/($B9-D$5))/(1+$B9)^'DCF Valuation'!$G$26+'DCF Valuation'!$C$54-'DCF Valuation'!$C$55)/'DCF Valuation'!$C$59) -> 82.571269 | E9: =IF($B9<=E$5,"n/m",(SUMPRODUCT('DCF Valuation'!$C$27:$G$27,1/(1+$B9)^'DCF Valuation'!$C$26:$G$26)+('DCF Valuation'!$G$27*(1+E$5)/($B9-E$5))/(1+$B9)^'DCF Valuation'!$G$26+'DCF Valuation'!$C$54-'DCF Valuation'!$C$55)/'DCF Valuation'!$C$59) -> 86.849942 | F9: =IF($B9<=F$5,"n/m",(SUMPRODUCT('DCF Valuation'!$C$27:$G$27,1/(1+$B9)^'DCF Valuation'!$C$26:$G$26)+('DCF Valuation'!$G$27*(1+F$5)/($B9-F$5))/(1+$B9)^'DCF Valuation'!$G$26+'DCF Valuation'!$C$54-'DCF Valuation'!$C$55)/'DCF Valuation'!$C$59) -> 91.713051 | G9: =IF($B9<=G$5,"n/m",(SUMPRODUCT('DCF Valuation'!$C$27:$G$27,1/(1+$B9)^'DCF Valuation'!$C$26:$G$26)+('DCF Valuation'!$G$27*(1+G$5)/($B9-G$5))/(1+$B9)^'DCF Valuation'!$G$26+'DCF Valuation'!$C$54-'DCF Valuation'!$C$55)/'DCF Valuation'!$C$59) -> 97.289119
B10: =$B$8+1% -> 0.10821026 | C10: =IF($B10<=C$5,"n/m",(SUMPRODUCT('DCF Valuation'!$C$27:$G$27,1/(1+$B10)^'DCF Valuation'!$C$26:$G$26)+('DCF Valuation'!$G$27*(1+C$5)/($B10-C$5))/(1+$B10)^'DCF Valuation'!$G$26+'DCF Valuation'!$C$54-'DCF Valuation'!$C$55)/'DCF Valuation'!$C$59) -> 74.188621 | D10: =IF($B10<=D$5,"n/m",(SUMPRODUCT('DCF Valuation'!$C$27:$G$27,1/(1+$B10)^'DCF Valuation'!$C$26:$G$26)+('DCF Valuation'!$G$27*(1+D$5)/($B10-D$5))/(1+$B10)^'DCF Valuation'!$G$26+'DCF Valuation'!$C$54-'DCF Valuation'!$C$55)/'DCF Valuation'!$C$59) -> 77.514538 | E10: =IF($B10<=E$5,"n/m",(SUMPRODUCT('DCF Valuation'!$C$27:$G$27,1/(1+$B10)^'DCF Valuation'!$C$26:$G$26)+('DCF Valuation'!$G$27*(1+E$5)/($B10-E$5))/(1+$B10)^'DCF Valuation'!$G$26+'DCF Valuation'!$C$54-'DCF Valuation'!$C$55)/'DCF Valuation'!$C$59) -> 81.240155 | F10: =IF($B10<=F$5,"n/m",(SUMPRODUCT('DCF Valuation'!$C$27:$G$27,1/(1+$B10)^'DCF Valuation'!$C$26:$G$26)+('DCF Valuation'!$G$27*(1+F$5)/($B10-F$5))/(1+$B10)^'DCF Valuation'!$G$26+'DCF Valuation'!$C$54-'DCF Valuation'!$C$55)/'DCF Valuation'!$C$59) -> 85.442131 | G10: =IF($B10<=G$5,"n/m",(SUMPRODUCT('DCF Valuation'!$C$27:$G$27,1/(1+$B10)^'DCF Valuation'!$C$26:$G$26)+('DCF Valuation'!$G$27*(1+G$5)/($B10-G$5))/(1+$B10)^'DCF Valuation'!$G$26+'DCF Valuation'!$C$54-'DCF Valuation'!$C$55)/'DCF Valuation'!$C$59) -> 90.218068
B13: Base Case
B14: WACC | C14: ='DCF Valuation'!$J$21 -> 0.098210261
B15: Terminal Growth Rate | C15: ='DCF Valuation'!$J$22 -> 0.025
B16: Implied Share Price | C16: ='DCF Valuation'!$J$26 -> 93.241955
B17: Current Share Price | C17: ='DCF Valuation'!$J$27 -> 320.21
B18: Upside / (Downside) | C18: ='DCF Valuation'!$J$28 -> -0.70880998
